#VRML_SIM R2022b utf8

EXTERNPROTO "webots://projects/objects/backgrounds/protos/TexturedBackgroundLight.proto"

WorldInfo {
  info [
    ""
  ]
  basicTimeStep 1
}
Viewpoint {
  orientation 0 0 -1 1.5707963267948966
  position 0.0008231539711693742 1.3906107484945607 -0.1345733862409407
}
Robot {
  children [
    Emitter {
      channel 100
      allowedChannels [
        100
      ]
    }
    HingeJoint {
      jointParameters HingeJointParameters {
        axis 0 1 0
      }
      device [
        PositionSensor {
          name "sensor1"
        }
        RotationalMotor {
          name "motor1"
          controlPID 50 0 0
          maxVelocity 300
          maxTorque 14
        }
      ]
      endPoint DEF Hip Solid {
        rotation 0 1 0 0
        children [
          Shape {
            appearance PBRAppearance {
              baseColor 0 0 0
            }
            geometry DEF THIGH Mesh {
              url [
                "../protos/thigh_without_shell.STL"
              ]
            }
          }
          HingeJoint {
            jointParameters HingeJointParameters {
              axis 0 1 0
              anchor 0 0.046 0
              minStop -0.1
              maxStop 2.56
            }
            device [
              PositionSensor {
                name "sensor2"
              }
              RotationalMotor {
                name "motor2"
                controlPID 50 0 0
                maxVelocity 300
                minPosition -0.1
                maxPosition 2.56
                maxTorque 14
              }
            ]
            endPoint Solid {
              translation 0 0.04599999999999999 0
              rotation 0 1 0 0
              children [
                HingeJoint {
                  jointParameters HingeJointParameters {
                    axis 0 1 0
                    anchor -0.00388229 0.0065 -0.0144889
                  }
                  device [
                    PositionSensor {
                      name "pos2"
                    }
                  ]
                  endPoint Solid {
                    translation -0.0038822900000000105 0.006500000000000006 -0.014488900000000027
                    rotation 0 1 0 0
                    children [
                      HingeJoint {
                        jointParameters HingeJointParameters {
                          axis 0 1 0
                          anchor -0.0150471 0 -0.208585
                        }
                        endPoint Solid {
                          translation -0.01504709999999998 0 -0.208585
                          rotation 0 1 0 0
                          children [
                            DEF Foot Solid {
                              translation 0.09402 0 0.19909
                              children [
                                DEF TOE Shape {
                                  appearance PBRAppearance {
                                    baseColor 0 0 0
                                  }
                                  geometry Sphere {
                                    radius 0.02
                                    subdivision 3
                                  }
                                }
                              ]
                              physics Physics {
                                density -1
                                mass 0.02
                                centerOfMass [
                                  0 0 0
                                ]
                                inertiaMatrix [
                                  1e-06 1e-06 1e-06
                                  0 0 0
                                ]
                              }
                            }
                            HingeJoint {
                              jointParameters HingeJointParameters {
                                axis 0 1 0
                                anchor 0.01893 0 0.01307
                              }
                              device [
                                PositionSensor {
                                  name "knee_pos_sensor"
                                }
                              ]
                              endPoint SolidReference {
                                solidName "leg"
                              }
                            }
                            Shape {
                              appearance PBRAppearance {
                                baseColor 0 0 0
                              }
                              geometry DEF Leg Mesh {
                                url [
                                  "../protos/leg.STL"
                                ]
                              }
                            }
                          ]
                          boundingObject USE Leg
                          physics Physics {
                            density -1
                            mass 0.0797866
                            centerOfMass [
                              0.0442186 0 0.0690547
                            ]
                            inertiaMatrix [
                              0.00066592 0.00087332 0.00021075
                              0 -0.00036006 0
                            ]
                          }
                        }
                      }
                      Shape {
                        appearance PBRAppearance {
                          baseColor 0 1 1
                        }
                        geometry DEF LegLink Mesh {
                          url [
                            "../protos/leg_link.STL"
                          ]
                        }
                      }
                    ]
                    boundingObject USE LegLink
                    physics Physics {
                      density -1
                      mass 0.0351523
                      centerOfMass [
                        -0.010857 0 -0.101415
                      ]
                      inertiaMatrix [
                        0.0005228 0.00052772 5.12e-06
                        0 -4.66e-05 0
                      ]
                    }
                  }
                }
                Shape {
                  appearance PBRAppearance {
                    baseColor 1 0.3 0
                  }
                  geometry DEF Thigh2Knee Mesh {
                    url [
                      "../protos/thigh_to_knee.STL"
                    ]
                  }
                }
              ]
              boundingObject USE Thigh2Knee
              physics Physics {
                density -1
                mass 0.0302015
                centerOfMass [
                  -0.00306559 0.00796815 0.00410762
                ]
                inertiaMatrix [
                  5.15e-06 5.24e-06 5.08e-06
                  7.1e-07 -3.3e-07 -7.6e-07
                ]
              }
            }
          }
        ]
        name "leg"
        boundingObject USE THIGH
        physics Physics {
          density -1
          mass 1.02891
          centerOfMass [
            -0.003147 0.031419 -0.0204177
          ]
          inertiaMatrix [
            0.0047894 0.0040178 0.0019091
            0.0001697 -0.0003733 0.00109
          ]
        }
      }
    }
  ]
  name "SingleLeg"
  controller "leg_controller"
}
Robot {
  children [
    Receiver {
      channel 100
      allowedChannels [
        100
      ]
    }
  ]
  name "supervisor"
  controller "draw_foot_trail"
  supervisor TRUE
}
TexturedBackgroundLight {
}
Background {
  skyColor [
    1 1 1
  ]
}
